Workbook

Sheet Sheet1
B3: Row Labels | C3: Count of Full Name
B4: AWS Platform Engineering Internal Demands | C4: 29
B5: AWS Platform Engineering Project Demands | C5: 44
B6: AWS Platform Engineering Nore | C6: 4
B7: Grand Total | C7: 77

Sheet PublicCloudResourceList
A1: Full Name | B1: 521 ID | C1: Point of Contact | D1: Team | E1: Start Date | F1: End Date | G1: Billability
A2: Anusha Kandhee | B2: KHANDAN1 | C2: Jonnalagadda Srihari | D2: AWS Platform Engineering Project Demands
A3: Arepalli Gayathri | B3: GAYATAR1 | C3: Jonnalagadda Srihari | D3: AWS Platform Engineering Project Demands
A4: Ashish Mittal | B4: MITTAAS4 | C4: Jonnalagadda Srihari | D4: AWS Platform Engineering Internal Demands
A5: Balaji Rajendran | B5: RAJENBA2 | C5: Jonnalagadda Srihari | D5: AWS Platform Engineering Project Demands
A6: Busigari Surya Prasanth Reddy | B6: BUSIGSU1 | C6: Jonnalagadda Srihari | D6: AWS Platform Engineering Project Demands
A7: C Kalyan Kumar | B7: CKA3 | C7: Jonnalagadda Srihari | D7: AWS Platform Engineering Project Demands
A8: Chaitanya Latha Kolluru | B8: KOLLUCH4 | C8: Jonnalagadda Srihari | D8: AWS Platform Engineering Project Demands
A9: DEEPA KESA | B9: KESADE1 | C9: Jonnalagadda Srihari | D9: AWS Platform Engineering Internal Demands
A10: Devaraj Maniyamghat Damodharan | B10: DAMODDE2 | C10: Jonnalagadda Srihari | D10: AWS Platform Engineering Project Demands | F10: 46127
A11: Dilish Madduri | B11: MADDUDI2 | C11: Jonnalagadda Srihari | D11: AWS Platform Engineering Project Demands
A12: Rethvik Sai Doddapaneni | B12: DODDARE1 | C12: Jonnalagadda Srihari | D12: AWS Platform Engineering Internal Demands
A13: Dokka SVS Swamy | B13: SWAMYDO2 | C13: Jonnalagadda Srihari | D13: AWS Platform Engineering Project Demands
A14: E Naga Sudha Rani | B14: EDENA3 | C14: Jonnalagadda Srihari | D14: AWS Platform Engineering Internal Demands
A15: Elango Chinnaiya | B15: CHINNEL2 | C15: Jonnalagadda Srihari | D15: AWS Platform Engineering Project Demands
A16: Prasanthi Gavini | B16: PRASAGA5 | C16: Jonnalagadda Srihari | D16: AWS Platform Engineering Project Demands
A17: Hakeem Naseer Ahmed | B17: AHMEDNAQ | C17: Jonnalagadda Srihari | D17: AWS Platform Engineering Project Demands
A18: Hariharan K R | B18: KRHA1 | C18: Jonnalagadda Srihari | D18: AWS Platform Engineering Internal Demands
A19: Hema Bharathi Janapaneni | B19: JANAPHE1 | C19: Jonnalagadda Srihari | D19: AWS Platform Engineering Project Demands | E19: 45805
A20: Jashva Sabbu | B20: SABBUJA1 | C20: Jonnalagadda Srihari | D20: AWS Platform Engineering Project Demands
A21: Jawahar Jyoti Goswami | B21: GOSWAJA2 | C21: Jonnalagadda Srihari | D21: AWS Platform Engineering Project Demands
A22: Jogiraju Sirisipalli | B22: SIRISJO1 | C22: Jonnalagadda Srihari | D22: AWS Platform Engineering Project Demands
A23: K Tharun Kumar | B23: KTH6 | C23: Jonnalagadda Srihari | D23: AWS Platform Engineering Project Demands
A24: Kapil Kumar Yadav | B24: YADAVKA3 | C24: Jonnalagadda Srihari | D24: AWS Platform Engineering Project Demands
A25: Keshava J R | B25: JRKE1 | C25: Jonnalagadda Srihari | D25: AWS Platform Engineering Project Demands
A26: Suneel Kumar Komandla | B26: KOMANSU1 | C26: Jonnalagadda Srihari | D26: AWS Platform Engineering Project Demands
A27: Manoj Kumar Karoju | B27: KAROJMA1 | C27: Jonnalagadda Srihari | D27: AWS Platform Engineering Project Demands
A28: Mohammed Mohsin Ali | B28: ALIMO1I | C28: Kishore Rohera | D28: Azure TDE
A29: Mr. Konanki Naga Sreehari | B29: KONANSR1 | C29: Kishore Rohera | D29: Azure TDE
A30: Mr. Neeraj S Chavan | B30: CHAVANE2 | C30: Kishore Rohera | D30: Azure TDE
A31: Mr. Praveen Rayidi | B31: RAYIDPR1 | C31: Jonnalagadda Srihari | D31: AWS Platform Engineering Project Demands
... A54: Venkataramana Budisetti | B54: BUDISVE1 | C54: Jonnalagadda Srihari | D54: AWS Platform Engineering Internal Demands
A55: Venu Madhav Reddy | B55: CHILUVE3 | C55: Jonnalagadda Srihari | D55: AWS Platform Engineering Internal Demands | G55: Non-Billable
A56: Vignesh Ponraj | B56: PVI6 | C56: Jonnalagadda Srihari | D56: AWS Platform Engineering Internal Demands
A57: Vikram Sanugula | B57: SANUGVI1 | C57: Jonnalagadda Srihari | D57: AWS Platform Engineering Internal Demands
A58: Vimit Vimit | B58: VIMITVI1 | C58: Jonnalagadda Srihari | D58: AWS Platform Engineering Internal Demands
A59: Vysyaraju Prudhviraju | B59: VYSYAPR1 | C59: Jonnalagadda Srihari | D59: AWS Platform Engineering Project Demands
A60: Amrendra Kumar | B60: KUMARA9T | C60: Nilotpal Das | D60: AWS TDE
A61: Sarathchandra Bhaskara | B61: CHANDS1E | C61: Nilotpal Das | D61: AWS TDE
A62: Mr. Varun Gollapalli | B62: GOLLAVA4 | C62: Prashant Shah | D62: AWS SDE
...

Sheet Sheet2
G1: Internal
A2: Arepalli Gayathri | B2: =VLOOKUP(A2,PublicCloudResourceList!A:A,1,FALSE) -> Arepalli Gayathri | G2: Prem Prakash | H2: =VLOOKUP(G2,PublicCloudResourceList!A:A,1,FALSE) -> Prem Prakash
A3: Arvind Kumar Tiwari | B3: =VLOOKUP(A3,PublicCloudResourceList!A:A,1,FALSE) -> Arvind Kumar Tiwari | G3: Chandana Charita Vaddadi | H3: =VLOOKUP(G3,PublicCloudResourceList!A:A,1,FALSE) -> Chandana Charita Vaddadi
A4: Busigari Surya Prasanth Reddy | B4: =VLOOKUP(A4,PublicCloudResourceList!A:A,1,FALSE) -> Busigari Surya Prasanth Reddy | G4: Radha Kanaka Ratnam Tetali | H4: =VLOOKUP(G4,PublicCloudResourceList!A:A,1,FALSE) -> Radha Kanaka Ratnam Tetali
A5: Ms. Chaytali Gajarmal | B5: =VLOOKUP(A5,PublicCloudResourceList!A:A,1,FALSE) -> Ms. Chaytali Gajarmal | G5: Deepa Kesa | H5: =VLOOKUP(G5,PublicCloudResourceList!A:A,1,FALSE) -> DEEPA KESA
A6: Prasanthi Gavini | B6: =VLOOKUP(A6,PublicCloudResourceList!A:A,1,FALSE) -> Prasanthi Gavini | G6: Sandeep Sree Ram | H6: =VLOOKUP(G6,PublicCloudResourceList!A:A,1,FALSE) -> Sandeep Sree Ram
A7: Hakeem Naseer Ahmed | B7: =VLOOKUP(A7,PublicCloudResourceList!A:A,1,FALSE) -> Hakeem Naseer Ahmed | G7: Sveta Satish Shenoy | H7: =VLOOKUP(G7,PublicCloudResourceList!A:A,1,FALSE) -> Sveta Satish Shenoy
A8: Elango Chinnaiya | B8: =VLOOKUP(A8,PublicCloudResourceList!A:A,1,FALSE) -> Elango Chinnaiya | G8: Sridhar Achary Nagavelli | H8: =VLOOKUP(G8,PublicCloudResourceList!A:A,1,FALSE) -> Sridhar Achary Nagavelli
A9: Hema Bharathi Janapaneni | B9: =VLOOKUP(A9,PublicCloudResourceList!A:A,1,FALSE) -> Hema Bharathi Janapaneni | G9: Rethvik Sai Doddapaneni | H9: =VLOOKUP(G9,PublicCloudResourceList!A:A,1,FALSE) -> Rethvik Sai Doddapaneni
A10: Keshava J R | B10: =VLOOKUP(A10,PublicCloudResourceList!A:A,1,FALSE) -> Keshava J R | G10: Goutham Reddy Katukuri | H10: =VLOOKUP(G10,PublicCloudResourceList!A:A,1,FALSE) -> Goutham Reddy Katukuri
A11: Siva Sagar Mavuduri | B11: =VLOOKUP(A11,PublicCloudResourceList!A:A,1,FALSE) -> Siva Sagar Mavuduri | G11: Savitha Puttuluri | H11: =VLOOKUP(G11,PublicCloudResourceList!A:A,1,FALSE) -> Savitha Puttuluri
A12: Vysyaraju Prudhviraju | B12: =VLOOKUP(A12,PublicCloudResourceList!A:A,1,FALSE) -> Vysyaraju Prudhviraju | G12: Neha Shridhar Gundkal | H12: =VLOOKUP(G12,PublicCloudResourceList!A:A,1,FALSE) -> Neha Shridhar Gundkal
A13: Anusha Kandhee | B13: =VLOOKUP(A13,PublicCloudResourceList!A:A,1,FALSE) -> Anusha Kandhee | G13: Mubarak Amin Mujawar | H13: =VLOOKUP(G13,PublicCloudResourceList!A:A,1,FALSE) -> Mubarak Amin Mujawar
... A41: Gupta, Akhil | B41: =VLOOKUP(A41,PublicCloudResourceList!A:A,1,FALSE) -> Gupta, Akhil | G41: Vikram Sanugula | H41: =VLOOKUP(G41,PublicCloudResourceList!A:A,1,FALSE) -> Vikram Sanugula
A42: Assath Mohammed | B42: =VLOOKUP(A42,PublicCloudResourceList!A:A,1,FALSE) -> Assath Mohammed
A43: Indukuri Anjaneya Shiva Rama Raju | B43: =VLOOKUP(A43,PublicCloudResourceList!A:A,1,FALSE) -> #N/A
A44: Pranav Vinay Kunkerkar | B44: =VLOOKUP(A44,PublicCloudResourceList!A:A,1,FALSE) -> Pranav Vinay Kunkerkar
A45: Dokka SVS Swamy | B45: =VLOOKUP(A45,PublicCloudResourceList!A:A,1,FALSE) -> Dokka SVS Swamy
A46: C Kalyan Kumar | B46: =VLOOKUP(A46,PublicCloudResourceList!A:A,1,FALSE) -> C Kalyan Kumar
A47: Chaitanya Latha Kolluru | B47: =VLOOKUP(A47,PublicCloudResourceList!A:A,1,FALSE) -> Chaitanya Latha Kolluru
A48: Neeraj Singh Sisodia | B48: =VLOOKUP(A48,PublicCloudResourceList!A:A,1,FALSE) -> Neeraj Singh Sisodia
A49: Mr. Praveen Rayidi | B49: =VLOOKUP(A49,PublicCloudResourceList!A:A,1,FALSE) -> Mr. Praveen Rayidi

Sheet Deleted List
A1: Full Name | B1: 521 ID | C1: Point of Contact | D1: Team | E1: Start Date | F1: End Date | G1: Billability
A2: Aashish Raut | B2: RAUTAA1 | C2: Jonnalagadda Srihari | D2: AWS Platform Engineering Internal Demands | F2: 45853 | G2: Billable
A3: Charitha Siva Venkata Kanuri | B3: SIVAVCH2 | C3: Jonnalagadda Srihari | D3: AWS Platform Engineering Project Demands | F3: 46053
A4: Ganesh Baliram Sultane | B4: SULTAGA2 | C4: Jonnalagadda Srihari | D4: AWS Platform Engineering Internal Demands | F4: 46053
A5: Naresh Kumar | B5: KUMARN5N | C5: Jonnalagadda Srihari | D5: AWS Platform Engineering Project Demands | F5: 46080
A6: P Sunil Kumar | B6: KUMARSJZ | C6: Jonnalagadda Srihari | D6: AWS Platform Engineering Project Demands | F6: 46080
A7: Panakam Divya | B7: PANAKDI1 | C7: Jonnalagadda Srihari | D7: AWS Platform Engineering Internal Demands | F7: 46053
A8: Premchander Jebastian | B8: CHANDP1D | C8: Jonnalagadda Srihari | D8: AWS Platform Engineering Project Demands | F8: 46030
A9: Ravi Kiran Deyyala | B9: DEYYARA2 | C9: Jonnalagadda Srihari | D9: AWS Platform Engineering Internal Demands | F9: 46053
A10: Suganesh Nageshwaran V | B10: NAGESSU2 | C10: Jonnalagadda Srihari | D10: AWS Platform Engineering Project Demands | F10: 46073
A11: Sumitra Bhagirathi Dalai | B11: DALAISU1 | C11: Jonnalagadda Srihari | D11: AWS Platform Engineering Internal Demands | F11: 46069
A12: Vamshi Venkat Rajesh Machiraju | B12: MACHIVA3 | C12: Jonnalagadda Srihari | D12: AWS Platform Engineering Project Demands | F12: 46053
A13: Karthik Prakash | B13: PRAKAKA4 | C13: Jonnalagadda Srihari | D13: AWS Platform Engineering Project Demands | F13: 46112
A14: Pravallika Rallapalli | B14: RALLAPR3 | C14: Jonnalagadda Srihari | D14: AWS Platform Engineering Project Demands | F14: 46091
